Workbook
Name ControlIDs: 'Control Assessment'!$E$7:$E$106
Name EvidenceIDs: 'Evidence Tracker'!$E$7:$E$106
Name RiskIDs: 'Risk Register'!$E$7:$E$106
Name RiskTitles: 'Risk Register'!$F$7:$F$106

Sheet Dashboard
AE2: Rating | AF2: Risks
AE3: Low | AF3: =COUNTIFS('Risk Register'!$Y$7:$Y$106,1,'Risk Register'!$N$7:$N$106,AE3) -> 0
AE4: Moderate | AF4: =COUNTIFS('Risk Register'!$Y$7:$Y$106,1,'Risk Register'!$N$7:$N$106,AE4) -> 0
F5: GRC PROJECT 01 / EXECUTIVE WORKSPACE / TRAINING SCENARIO | AE5: High | AF5: =COUNTIFS('Risk Register'!$Y$7:$Y$106,1,'Risk Register'!$N$7:$N$106,AE5) -> 4
L6: VALIDATION STATUS | T6: INHERENT RATING | AE6: Critical | AF6: =COUNTIFS('Risk Register'!$Y$7:$Y$106,1,'Risk Register'!$N$7:$N$106,AE6) -> 0
L7: All | T7: All
F8: Risk filters apply to the risk cards, distribution and heatmap. Evidence and action summaries include all records.
AE9: Evidence stage | AF9: Requests
F10: RISKS IN VIEW | L10: HIGH / CRITICAL | R10: VALIDATED IN VIEW | X10: PENDING VALIDATION | AE10: Planned | AF10: =COUNTIFS('Evidence Tracker'!$E$7:$E$106,"<>",'Evidence Tracker'!$N$7:$N$106,"Planned request") -> 4
AE11: Requested | AF11: =COUNTIFS('Evidence Tracker'!$E$7:$E$106,"<>",'Evidence Tracker'!$N$7:$N$106,"Requested") -> 0
F12: =SUM('Risk Register'!$Y$7:$Y$106) -> 4 | L12: =COUNTIFS('Risk Register'!$Y$7:$Y$106,1,'Risk Register'!$N$7:$N$106,"High")+COUNTIFS('Risk Register'!$Y$7:$Y$106,1,'Risk Register'!$N$7:$N$106,"Critical") -> 4 | R12: =COUNTIFS('Risk Register'!$Y$7:$Y$106,1,'Risk Register'!$Q$7:$Q$106,"Validated") -> 0 | X12: =COUNTIFS('Risk Register'!$Y$7:$Y$106,1,'Risk Register'!$Q$7:$Q$106,"Pending validation") -> 4 | AE12: Received | AF12: =COUNTIFS('Evidence Tracker'!$E$7:$E$106,"<>",'Evidence Tracker'!$N$7:$N$106,"Received") -> 0
AE13: In review | AF13: =COUNTIFS('Evidence Tracker'!$E$7:$E$106,"<>",'Evidence Tracker'!$N$7:$N$106,"Under review") -> 0
AE14: Reviewed | AF14: =COUNTIFS('Evidence Tracker'!$E$7:$E$106,"<>",'Evidence Tracker'!$N$7:$N$106,"Reviewed") -> 0
F15: INHERENT RISK DISTRIBUTION | R15: LIKELIHOOD × IMPACT
AE16: ='Scoring Methodology'!F16 -> 6 | AF16: ='Scoring Methodology'!F17 -> 12 | AG16: ='Scoring Methodology'!F18 -> 20
V17: 1 | W17: 2 | X17: 3 | Y17: 4 | Z17: 5 | AE17: =IF($AE$20=0,"",INDEX('Risk Register'!$N$7:$N$106,$AE$20)) -> High
U18: 5 | V18: =COUNTIFS('Risk Register'!$Y$7:$Y$106,1,'Risk Register'!$K$7:$K$106,$U18,'Risk Register'!$L$7:$L$106,V$17) -> 0 | W18: =COUNTIFS('Risk Register'!$Y$7:$Y$106,1,'Risk Register'!$K$7:$K$106,$U18,'Risk Register'!$L$7:$L$106,W$17) -> 0 | X18: =COUNTIFS('Risk Register'!$Y$7:$Y$106,1,'Risk Register'!$K$7:$K$106,$U18,'Risk Register'!$L$7:$L$106,X$17) -> 0 | Y18: =COUNTIFS('Risk Register'!$Y$7:$Y$106,1,'Risk Register'!$K$7:$K$106,$U18,'Risk Register'!$L$7:$L$106,Y$17) -> 0 | Z18: =COUNTIFS('Risk Register'!$Y$7:$Y$106,1,'Risk Register'!$K$7:$K$106,$U18,'Risk Register'!$L$7:$L$106,Z$17) -> 0
U19: 4 | V19: =COUNTIFS('Risk Register'!$Y$7:$Y$106,1,'Risk Register'!$K$7:$K$106,$U19,'Risk Register'!$L$7:$L$106,V$17) -> 0 | W19: =COUNTIFS('Risk Register'!$Y$7:$Y$106,1,'Risk Register'!$K$7:$K$106,$U19,'Risk Register'!$L$7:$L$106,W$17) -> 0 | X19: =COUNTIFS('Risk Register'!$Y$7:$Y$106,1,'Risk Register'!$K$7:$K$106,$U19,'Risk Register'!$L$7:$L$106,X$17) -> 0 | Y19: =COUNTIFS('Risk Register'!$Y$7:$Y$106,1,'Risk Register'!$K$7:$K$106,$U19,'Risk Register'!$L$7:$L$106,Y$17) -> 0 | Z19: =COUNTIFS('Risk Register'!$Y$7:$Y$106,1,'Risk Register'!$K$7:$K$106,$U19,'Risk Register'!$L$7:$L$106,Z$17) -> 0
U20: 3 | V20: =COUNTIFS('Risk Register'!$Y$7:$Y$106,1,'Risk Register'!$K$7:$K$106,$U20,'Risk Register'!$L$7:$L$106,V$17) -> 0 | W20: =COUNTIFS('Risk Register'!$Y$7:$Y$106,1,'Risk Register'!$K$7:$K$106,$U20,'Risk Register'!$L$7:$L$106,W$17) -> 0 | X20: =COUNTIFS('Risk Register'!$Y$7:$Y$106,1,'Risk Register'!$K$7:$K$106,$U20,'Risk Register'!$L$7:$L$106,X$17) -> 0 | Y20: =COUNTIFS('Risk Register'!$Y$7:$Y$106,1,'Risk Register'!$K$7:$K$106,$U20,'Risk Register'!$L$7:$L$106,Y$17) -> 4 | Z20: =COUNTIFS('Risk Register'!$Y$7:$Y$106,1,'Risk Register'!$K$7:$K$106,$U20,'Risk Register'!$L$7:$L$106,Z$17) -> 0 | AE20: =IFERROR(MATCH(X29,'Risk Register'!$E$7:$E$106,0),0) -> 1
U21: 2 | V21: =COUNTIFS('Risk Register'!$Y$7:$Y$106,1,'Risk Register'!$K$7:$K$106,$U21,'Risk Register'!$L$7:$L$106,V$17) -> 0 | W21: =COUNTIFS('Risk Register'!$Y$7:$Y$106,1,'Risk Register'!$K$7:$K$106,$U21,'Risk Register'!$L$7:$L$106,W$17) -> 0 | X21: =COUNTIFS('Risk Register'!$Y$7:$Y$106,1,'Risk Register'!$K$7:$K$106,$U21,'Risk Register'!$L$7:$L$106,X$17) -> 0 | Y21: =COUNTIFS('Risk Register'!$Y$7:$Y$106,1,'Risk Register'!$K$7:$K$106,$U21,'Risk Register'!$L$7:$L$106,Y$17) -> 0 | Z21: =COUNTIFS('Risk Register'!$Y$7:$Y$106,1,'Risk Register'!$K$7:$K$106,$U21,'Risk Register'!$L$7:$L$106,Z$17) -> 0
U22: 1 | V22: =COUNTIFS('Risk Register'!$Y$7:$Y$106,1,'Risk Register'!$K$7:$K$106,$U22,'Risk Register'!$L$7:$L$106,V$17) -> 0 | W22: =COUNTIFS('Risk Register'!$Y$7:$Y$106,1,'Risk Register'!$K$7:$K$106,$U22,'Risk Register'!$L$7:$L$106,W$17) -> 0 | X22: =COUNTIFS('Risk Register'!$Y$7:$Y$106,1,'Risk Register'!$K$7:$K$106,$U22,'Risk Register'!$L$7:$L$106,X$17) -> 0 | Y22: =COUNTIFS('Risk Register'!$Y$7:$Y$106,1,'Risk Register'!$K$7:$K$106,$U22,'Risk Register'!$L$7:$L$106,Y$17) -> 0 | Z22: =COUNTIFS('Risk Register'!$Y$7:$Y$106,1,'Risk Register'!$K$7:$K$106,$U22,'Risk Register'!$L$7:$L$106,Z$17) -> 0
R24: Rows: likelihood 5 → 1. Columns: impact 1 → 5. Each cell counts risks; color reflects the score band.
F28: =IF(F12=0,"No risks match these filters.","Risk distribution total: "&SUM(AF3:AF6)&" / "&F12&" risks in view") -> Risk distribution total: 4 / 4 risks in view
R29: SELECT RISK ID | S29: SELECT RISK | T29: SELECT RISK | U29: SELECT RISK | V29: SELECT RISK | W29: SELECT RISK | X29: R-001 | Y29: R-001 | Z29: R-001 | AA29: R-001 | AB29: R-001
F30: EVIDENCE COLLECTION | R30: =IF($AE$20=0,"SELECT A VALID RISK",INDEX('Risk Register'!$F$7:$F$106,$AE$20)&" / ASSESSMENT SNAPSHOT") -> Missing MFA / ASSESSMENT SNAPSHOT | AE30: =IF(OR('Remediation Tracker'!E7="",AND('Remediation Tracker'!I7="Approved",'Remediation Tracker'!J7="Completed",ISNUMBER('Remediation Tracker'!L7),'Remediation Tracker'!L7>0,'Remediation Tracker'!L7<=TODAY(),'Remediation Tracker'!N7="Validated",IFERROR(AND('Remediation Tracker'!M7<>"",COUNTIF('Evidence Tracker'!$E$7:$E$106,'Remediation Tracker'!M7)=1,ISNUMBER(INDEX('Evidence Tracker'!$M$7:$M$106,MATCH('Remediation Tracker'!M7,'Evidence Tracker'!$E$7:$E$106,0))),LEN(TRIM(INDEX('Evidence Tracker'!$O$7:$O$106,MATCH('Remediation Tracker'!M7,'Evidence Tracker'!$E$7:$E$106,0))))>0,LEN(TRIM(INDEX('Evidence Tracker'!$P$7:$P$106,MATCH('Remediation Tracker'!M7,'Evidence Tracker'!$E$7:$E$106,0))))>0,COUNTIFS('Evidence Tracker'!$E$7:$E$106,'Remediation Tracker'!M7,'Evidence Tracker'!$F$7:$F$106,'Remediation Tracker'!F7,'Evidence Tracker'!$N$7:$N$106,"Reviewed",'Evidence Tracker'!$Q$7:$Q$106,"Validated",'Evidence Tracker'!$M$7:$M$106,">0",'Evidence Tracker'!$M$7:$M$106,"<="&TODAY())=1),FALSE))),0,IFERROR(INDEX('Risk Register'!$M$7:$M$106,MATCH('Remediation Tracker'!F7,'Risk Register'!$E$7:$E$106,0)),0)*10000+IF(AND(ISNUMBER('Remediation Tracker'!K7),'Remediation Tracker'!K7<TODAY(),'Remediation Tracker'!J7<>"Completed"),1000,0)+107-ROW('Remediation Tracker'!E7)) -> 120100
AE31: =IF(OR('Remediation Tracker'!E8="",AND('Remediation Tracker'!I8="Approved",'Remediation Tracker'!J8="Completed",ISNUMBER('Remediation Tracker'!L8),'Remediation Tracker'!L8>0,'Remediation Tracker'!L8<=TODAY(),'Remediation Tracker'!N8="Validated",IFERROR(AND('Remediation Tracker'!M8<>"",COUNTIF('Evidence Tracker'!$E$7:$E$106,'Remediation Tracker'!M8)=1,ISNUMBER(INDEX('Evidence Tracker'!$M$7:$M$106,MATCH('Remediation Tracker'!M8,'Evidence Tracker'!$E$7:$E$106,0))),LEN(TRIM(INDEX('Evidence Tracker'!$O$7:$O$106,MATCH('Remediation Tracker'!M8,'Evidence Tracker'!$E$7:$E$106,0))))>0,LEN(TRIM(INDEX('Evidence Tracker'!$P$7:$P$106,MATCH('Remediation Tracker'!M8,'Evidence Tracker'!$E$7:$E$106,0))))>0,COUNTIFS('Evidence Tracker'!$E$7:$E$106,'Remediation Tracker'!M8,'Evidence Tracker'!$F$7:$F$106,'Remediation Tracker'!F8,'Evidence Tracker'!$N$7:$N$106,"Reviewed",'Evidence Tracker'!$Q$7:$Q$106,"Validated",'Evidence Tracker'!$M$7:$M$106,">0",'Evidence Tracker'!$M$7:$M$106,"<="&TODAY())=1),FALSE))),0,IFERROR(INDEX('Risk Register'!$M$7:$M$106,MATCH('Remediation Tracker'!F8,'Risk Register'!$E$7:$E$106,0)),0)*10000+IF(AND(ISNUMBER('Remediation Tracker'!K8),'Remediation Tracker'!K8<TODAY(),'Remediation Tracker'!J8<>"Completed"),1000,0)+107-ROW('Remediation Tracker'!E8)) -> 120099
R32: =IF($AE$20=0,"No risk selected",INDEX('Risk Register'!$F$7:$F$106,$AE$20)) -> Missing MFA | Y32: =IF($AE$20=0,"",INDEX('Risk Register'!$M$7:$M$106,$AE$20)&" / "&INDEX('Risk Register'!$N$7:$N$106,$AE$20)) -> 12 / High | AE32: =IF(OR('Remediation Tracker'!E9="",AND('Remediation Tracker'!I9="Approved",'Remediation Tracker'!J9="Completed",ISNUMBER('Remediation Tracker'!L9),'Remediation Tracker'!L9>0,'Remediation Tracker'!L9<=TODAY(),'Remediation Tracker'!N9="Validated",IFERROR(AND('Remediation Tracker'!M9<>"",COUNTIF('Evidence Tracker'!$E$7:$E$106,'Remediation Tracker'!M9)=1,ISNUMBER(INDEX('Evidence Tracker'!$M$7:$M$106,MATCH('Remediation Tracker'!M9,'Evidence Tracker'!$E$7:$E$106,0))),LEN(TRIM(INDEX('Evidence Tracker'!$O$7:$O$106,MATCH('Remediation Tracker'!M9,'Evidence Tracker'!$E$7:$E$106,0))))>0,LEN(TRIM(INDEX('Evidence Tracker'!$P$7:$P$106,MATCH('Remediation Tracker'!M9,'Evidence Tracker'!$E$7:$E$106,0))))>0,COUNTIFS('Evidence Tracker'!$E$7:$E$106,'Remediation Tracker'!M9,'Evidence Tracker'!$F$7:$F$106,'Remediation Tracker'!F9,'Evidence Tracker'!$N$7:$N$106,"Reviewed",'Evidence Tracker'!$Q$7:$Q$106,"Validated",'Evidence Tracker'!$M$7:$M$106,">0",'Evidence Tracker'!$M$7:$M$106,"<="&TODAY())=1),FALSE))),0,IFERROR(INDEX('Risk Register'!$M$7:$M$106,MATCH('Remediation Tracker'!F9,'Risk Register'!$E$7:$E$106,0)),0)*10000+IF(AND(ISNUMBER('Remediation Tracker'!K9),'Remediation Tracker'!K9<TODAY(),'Remediation Tracker'!J9<>"Completed"),1000,0)+107-ROW('Remediation Tracker'!E9)) -> 120098
AE33: =IF(OR('Remediation Tracker'!E10="",AND('Remediation Tracker'!I10="Approved",'Remediation Tracker'!J10="Completed",ISNUMBER('Remediation Tracker'!L10),'Remediation Tracker'!L10>0,'Remediation Tracker'!L10<=TODAY(),'Remediation Tracker'!N10="Validated",IFERROR(AND('Remediation Tracker'!M10<>"",COUNTIF('Evidence Tracker'!$E$7:$E$106,'Remediation Tracker'!M10)=1,ISNUMBER(INDEX('Evidence Tracker'!$M$7:$M$106,MATCH('Remediation Tracker'!M10,'Evidence Tracker'!$E$7:$E$106,0))),LEN(TRIM(INDEX('Evidence Tracker'!$O$7:$O$106,MATCH('Remediation Tracker'!M10,'Evidence Tracker'!$E$7:$E$106,0))))>0,LEN(TRIM(INDEX('Evidence Tracker'!$P$7:$P$106,MATCH('Remediation Tracker'!M10,'Evidence Tracker'!$E$7:$E$106,0))))>0,COUNTIFS('Evidence Tracker'!$E$7:$E$106,'Remediation Tracker'!M10,'Evidence Tracker'!$F$7:$F$106,'Remediation Tracker'!F10,'Evidence Tracker'!$N$7:$N$106,"Reviewed",'Evidence Tracker'!$Q$7:$Q$106,"Validated",'Evidence Tracker'!$M$7:$M$106,">0",'Evidence Tracker'!$M$7:$M$106,"<="&TODAY())=1),FALSE))),0,IFERROR(INDEX('Risk Register'!$M$7:$M$106,MATCH('Remediation Tracker'!F10,'Risk Register'!$E$7:$E$106,0)),0)*10000+IF(AND(ISNUMBER('Remediation Tracker'!K10),'Remediation Tracker'!K10<TODAY(),'Remediation Tracker'!J10<>"Completed"),1000,0)+107-ROW('Remediation Tracker'!E10)) -> 120097
AE34: =IF(OR('Remediation Tracker'!E11="",AND('Remediation Tracker'!I11="Approved",'Remediation Tracker'!J11="Completed",ISNUMBER('Remediation Tracker'!L11),'Remediation Tracker'!L11>0,'Remediation Tracker'!L11<=TODAY(),'Remediation Tracker'!N11="Validated",IFERROR(AND('Remediation Tracker'!M11<>"",COUNTIF('Evidence Tracker'!$E$7:$E$106,'Remediation Tracker'!M11)=1,ISNUMBER(INDEX('Evidence Tracker'!$M$7:$M$106,MATCH('Remediation Tracker'!M11,'Evidence Tracker'!$E$7:$E$106,0))),LEN(TRIM(INDEX('Evidence Tracker'!$O$7:$O$106,MATCH('Remediation Tracker'!M11,'Evidence Tracker'!$E$7:$E$106,0))))>0,LEN(TRIM(INDEX('Evidence Tracker'!$P$7:$P$106,MATCH('Remediation Tracker'!M11,'Evidence Tracker'!$E$7:$E$106,0))))>0,COUNTIFS('Evidence Tracker'!$E$7:$E$106,'Remediation Tracker'!M11,'Evidence Tracker'!$F$7:$F$106,'Remediation Tracker'!F11,'Evidence Tracker'!$N$7:$N$106,"Reviewed",'Evidence Tracker'!$Q$7:$Q$106,"Validated",'Evidence Tracker'!$M$7:$M$106,">0",'Evidence Tracker'!$M$7:$M$106,"<="&TODAY())=1),FALSE))),0,IFERROR(INDEX('Risk Register'!$M$7:$M$106,MATCH('Remediation Tracker'!F11,'Risk Register'!$E$7:$E$106,0)),0)*10000+IF(AND(ISNUMBER('Remediation Tracker'!K11),'Remediation Tracker'!K11<TODAY(),'Remediation Tracker'!J11<>"Completed"),1000,0)+107-ROW('Remediation Tracker'!E11)) -> 0
R35: =IF($AE$20=0,"Choose a risk above.","Validation: "&INDEX('Risk Register'!$Q$7:$Q$106,$AE$20)&". Owner: "&INDEX('Risk Register'!$O$7:$O$106,$AE$20)&". Workflow: "&INDEX('Risk Register'!$R$7:$R$106,$AE$20)&". See the scorecard and actions below for evidence and approval needs.") -> Validation: Pending validation. Owner: Security owner - proposed. Workflow: Proposed. See the scorecard and actions below for evidence and approval needs. | AE35: =IF(OR('Remediation Tracker'!E12="",AND('Remediation Tracker'!I12="Approved",'Remediation Tracker'!J12="Completed",ISNUMBER('Remediation Tracker'!L12),'Remediation Tracker'!L12>0,'Remediation Tracker'!L12<=TODAY(),'Remediation Tracker'!N12="Validated",IFERROR(AND('Remediation Tracker'!M12<>"",COUNTIF('Evidence Tracker'!$E$7:$E$106,'Remediation Tracker'!M12)=1,ISNUMBER(INDEX('Evidence Tracker'!$M$7:$M$106,MATCH('Remediation Tracker'!M12,'Evidence Tracker'!$E$7:$E$106,0))),LEN(TRIM(INDEX('Evidence Tracker'!$O$7:$O$106,MATCH('Remediation Tracker'!M12,'Evidence Tracker'!$E$7:$E$106,0))))>0,LEN(TRIM(INDEX('Evidence Tracker'!$P$7:$P$106,MATCH('Remediation Tracker'!M12,'Evidence Tracker'!$E$7:$E$106,0))))>0,COUNTIFS('Evidence Tracker'!$E$7:$E$106,'Remediation Tracker'!M12,'Evidence Tracker'!$F$7:$F$106,'Remediation Tracker'!F12,'Evidence Tracker'!$N$7:$N$106,"Reviewed",'Evidence Tracker'!$Q$7:$Q$106,"Validated",'Evidence Tracker'!$M$7:$M$106,">0",'Evidence Tracker'!$M$7:$M$106,"<="&TODAY())=1),FALSE))),0,IFERROR(INDEX('Risk Register'!$M$7:$M$106,MATCH('Remediation Tracker'!F12,'Risk Register'!$E$7:$E$106,0)),0)*10000+IF(AND(ISNUMBER('Remediation Tracker'!K12),'Remediation Tracker'!K12<TODAY(),'Remediation Tracker'!J12<>"Completed"),1000,0)+107-ROW('Remediation Tracker'!E12)) -> 0
AE36: =IF(OR('Remediation Tracker'!E13="",AND('Remediation Tracker'!I13="Approved",'Remediation Tracker'!J13="Completed",ISNUMBER('Remediation Tracker'!L13),'Remediation Tracker'!L13>0,'Remediation Tracker'!L13<=TODAY(),'Remediation Tracker'!N13="Validated",IFERROR(AND('Remediation Tracker'!M13<>"",COUNTIF('Evidence Tracker'!$E$7:$E$106,'Remediation Tracker'!M13)=1,ISNUMBER(INDEX('Evidence Tracker'!$M$7:$M$106,MATCH('Remediation Tracker'!M13,'Evidence Tracker'!$E$7:$E$106,0))),LEN(TRIM(INDEX('Evidence Tracker'!$O$7:$O$106,MATCH('Remediation Tracker'!M13,'Evidence Tracker'!$E$7:$E$106,0))))>0,LEN(TRIM(INDEX('Evidence Tracker'!$P$7:$P$106,MATCH('Remediation Tracker'!M13,'Evidence Tracker'!$E$7:$E$106,0))))>0,COUNTIFS('Evidence Tracker'!$E$7:$E$106,'Remediation Tracker'!M13,'Evidence Tracker'!$F$7:$F$106,'Remediation Tracker'!F13,'Evidence Tracker'!$N$7:$N$106,"Reviewed",'Evidence Tracker'!$Q$7:$Q$106,"Validated",'Evidence Tracker'!$M$7:$M$106,">0",'Evidence Tracker'!$M$7:$M$106,"<="&TODAY())=1),FALSE))),0,IFERROR(INDEX('Risk Register'!$M$7:$M$106,MATCH('Remediation Tracker'!F13,'Risk Register'!$E$7:$E$106,0)),0)*10000+IF(AND(ISNUMBER('Remediation Tracker'!K13),'Remediation Tracker'!K13<TODAY(),'Remediation Tracker'!J13<>"Completed"),1000,0)+107-ROW('Remediation Tracker'!E13)) -> 0
AE37: =IF(OR('Remediation Tracker'!E14="",AND('Remediation Tracker'!I14="Approved",'Remediation Tracker'!J14="Completed",ISNUMBER('Remediation Tracker'!L14),'Remediation Tracker'!L14>0,'Remediation Tracker'!L14<=TODAY(),'Remediation Tracker'!N14="Validated",IFERROR(AND('Remediation Tracker'!M14<>"",COUNTIF('Evidence Tracker'!$E$7:$E$106,'Remediation Tracker'!M14)=1,ISNUMBER(INDEX('Evidence Tracker'!$M$7:$M$106,MATCH('Remediation Tracker'!M14,'Evidence Tracker'!$E$7:$E$106,0))),LEN(TRIM(INDEX('Evidence Tracker'!$O$7:$O$106,MATCH('Remediation Tracker'!M14,'Evidence Tracker'!$E$7:$E$106,0))))>0,LEN(TRIM(INDEX('Evidence Tracker'!$P$7:$P$106,MATCH('Remediation Tracker'!M14,'Evidence Tracker'!$E$7:$E$106,0))))>0,COUNTIFS('Evidence Tracker'!$E$7:$E$106,'Remediation Tracker'!M14,'Evidence Tracker'!$F$7:$F$106,'Remediation Tracker'!F14,'Evidence Tracker'!$N$7:$N$106,"Reviewed",'Evidence Tracker'!$Q$7:$Q$106,"Validated",'Evidence Tracker'!$M$7:$M$106,">0",'Evidence Tracker'!$M$7:$M$106,"<="&TODAY())=1),FALSE))),0,IFERROR(INDEX('Risk Register'!$M$7:$M$106,MATCH('Remediation Tracker'!F14,'Risk Register'!$E$7:$E$106,0)),0)*10000+IF(AND(ISNUMBER('Remediation Tracker'!K14),'Remediation Tracker'!K14<TODAY(),'Remediation Tracker'!J14<>"Completed"),1000,0)+107-ROW('Remediation Tracker'!E14)) -> 0
AE38: =IF(OR('Remediation Tracker'!E15="",AND('Remediation Tracker'!I15="Approved",'Remediation Tracker'!J15="Completed",ISNUMBER('Remediation Tracker'!L15),'Remediation Tracker'!L15>0,'Remediation Tracker'!L15<=TODAY(),'Remediation Tracker'!N15="Validated",IFERROR(AND('Remediation Tracker'!M15<>"",COUNTIF('Evidence Tracker'!$E$7:$E$106,'Remediation Tracker'!M15)=1,ISNUMBER(INDEX('Evidence Tracker'!$M$7:$M$106,MATCH('Remediation Tracker'!M15,'Evidence Tracker'!$E$7:$E$106,0))),LEN(TRIM(INDEX('Evidence Tracker'!$O$7:$O$106,MATCH('Remediation Tracker'!M15,'Evidence Tracker'!$E$7:$E$106,0))))>0,LEN(TRIM(INDEX('Evidence Tracker'!$P$7:$P$106,MATCH('Remediation Tracker'!M15,'Evidence Tracker'!$E$7:$E$106,0))))>0,COUNTIFS('Evidence Tracker'!$E$7:$E$106,'Remediation Tracker'!M15,'Evidence Tracker'!$F$7:$F$106,'Remediation Tracker'!F15,'Evidence Tracker'!$N$7:$N$106,"Reviewed",'Evidence Tracker'!$Q$7:$Q$106,"Validated",'Evidence Tracker'!$M$7:$M$106,">0",'Evidence Tracker'!$M$7:$M$106,"<="&TODAY())=1),FALSE))),0,IFERROR(INDEX('Risk Register'!$M$7:$M$106,MATCH('Remediation Tracker'!F15,'Risk Register'!$E$7:$E$106,0)),0)*10000+IF(AND(ISNUMBER('Remediation Tracker'!K15),'Remediation Tracker'!K15<TODAY(),'Remediation Tracker'!J15<>"Completed"),1000,0)+107-ROW('Remediation Tracker'!E15)) -> 0
R39: VALIDATED EVIDENCE | AB39: =COUNTIFS('Evidence Tracker'!$E$7:$E$106,"<>",'Evidence Tracker'!$Q$7:$Q$106,"Validated") -> 0 | AE39: =IF(OR('Remediation Tracker'!E16="",AND('Remediation Tracker'!I16="Approved",'Remediation Tracker'!J16="Completed",ISNUMBER('Remediation Tracker'!L16),'Remediation Tracker'!L16>0,'Remediation Tracker'!L16<=TODAY(),'Remediation Tracker'!N16="Validated",IFERROR(AND('Remediation Tracker'!M16<>"",COUNTIF('Evidence Tracker'!$E$7:$E$106,'Remediation Tracker'!M16)=1,ISNUMBER(INDEX('Evidence Tracker'!$M$7:$M$106,MATCH('Remediation Tracker'!M16,'Evidence Tracker'!$E$7:$E$106,0))),LEN(TRIM(INDEX('Evidence Tracker'!$O$7:$O$106,MATCH('Remediation Tracker'!M16,'Evidence Tracker'!$E$7:$E$106,0))))>0,LEN(TRIM(INDEX('Evidence Tracker'!$P$7:$P$106,MATCH('Remediation Tracker'!M16,'Evidence Tracker'!$E$7:$E$106,0))))>0,COUNTIFS('Evidence Tracker'!$E$7:$E$106,'Remediation Tracker'!M16,'Evidence Tracker'!$F$7:$F$106,'Remediation Tracker'!F16,'Evidence Tracker'!$N$7:$N$106,"Reviewed",'Evidence Tracker'!$Q$7:$Q$106,"Validated",'Evidence Tracker'!$M$7:$M$106,">0",'Evidence Tracker'!$M$7:$M$106,"<="&TODAY())=1),FALSE))),0,IFERROR(INDEX('Risk Register'!$M$7:$M$106,MATCH('Remediation Tracker'!F16,'Risk Register'!$E$7:$E$106,0)),0)*10000+IF(AND(ISNUMBER('Remediation Tracker'!K16),'Remediation Tracker'!K16<TODAY(),'Remediation Tracker'!J16<>"Completed"),1000,0)+107-ROW('Remediation Tracker'!E16)) -> 0
R40: OVERDUE ACTIONS | AB40: =COUNTIFS('Remediation Tracker'!$O$7:$O$106,">0") -> 0 | AE40: =IF(OR('Remediation Tracker'!E17="",AND('Remediation Tracker'!I17="Approved",'Remediation Tracker'!J17="Completed",ISNUMBER('Remediation Tracker'!L17),'Remediation Tracker'!L17>0,'Remediation Tracker'!L17<=TODAY(),'Remediation Tracker'!N17="Validated",IFERROR(AND('Remediation Tracker'!M17<>"",COUNTIF('Evidence Tracker'!$E$7:$E$106,'Remediation Tracker'!M17)=1,ISNUMBER(INDEX('Evidence Tracker'!$M$7:$M$106,MATCH('Remediation Tracker'!M17,'Evidence Tracker'!$E$7:$E$106,0))),LEN(TRIM(INDEX('Evidence Tracker'!$O$7:$O$106,MATCH('Remediation Tracker'!M17,'Evidence Tracker'!$E$7:$E$106,0))))>0,LEN(TRIM(INDEX('Evidence Tracker'!$P$7:$P$106,MATCH('Remediation Tracker'!M17,'Evidence Tracker'!$E$7:$E$106,0))))>0,COUNTIFS('Evidence Tracker'!$E$7:$E$106,'Remediation Tracker'!M17,'Evidence Tracker'!$F$7:$F$106,'Remediation Tracker'!F17,'Evidence Tracker'!$N$7:$N$106,"Reviewed",'Evidence Tracker'!$Q$7:$Q$106,"Validated",'Evidence Tracker'!$M$7:$M$106,">0",'Evidence Tracker'!$M$7:$M$106,"<="&TODAY())=1),FALSE))),0,IFERROR(INDEX('Risk Register'!$M$7:$M$106,MATCH('Remediation Tracker'!F17,'Risk Register'!$E$7:$E$106,0)),0)*10000+IF(AND(ISNUMBER('Remediation Tracker'!K17),'Remediation Tracker'!K17<TODAY(),'Remediation Tracker'!J17<>"Completed"),1000,0)+107-ROW('Remediation Tracker'!E17)) -> 0
AE41: =IF(OR('Remediation Tracker'!E18="",AND('Remediation Tracker'!I18="Approved",'Remediation Tracker'!J18="Completed",ISNUMBER('Remediation Tracker'!L18),'Remediation Tracker'!L18>0,'Remediation Tracker'!L18<=TODAY(),'Remediation Tracker'!N18="Validated",IFERROR(AND('Remediation Tracker'!M18<>"",COUNTIF('Evidence Tracker'!$E$7:$E$106,'Remediation Tracker'!M18)=1,ISNUMBER(INDEX('Evidence Tracker'!$M$7:$M$106,MATCH('Remediation Tracker'!M18,'Evidence Tracker'!$E$7:$E$106,0))),LEN(TRIM(INDEX('Evidence Tracker'!$O$7:$O$106,MATCH('Remediation Tracker'!M18,'Evidence Tracker'!$E$7:$E$106,0))))>0,LEN(TRIM(INDEX('Evidence Tracker'!$P$7:$P$106,MATCH('Remediation Tracker'!M18,'Evidence Tracker'!$E$7:$E$106,0))))>0,COUNTIFS('Evidence Tracker'!$E$7:$E$106,'Remediation Tracker'!M18,'Evidence Tracker'!$F$7:$F$106,'Remediation Tracker'!F18,'Evidence Tracker'!$N$7:$N$106,"Reviewed",'Evidence Tracker'!$Q$7:$Q$106,"Validated",'Evidence Tracker'!$M$7:$M$106,">0",'Evidence Tracker'!$M$7:$M$106,"<="&TODAY())=1),FALSE))),0,IFERROR(INDEX('Risk Register'!$M$7:$M$106,MATCH('Remediation Tracker'!F18,'Risk Register'!$E$7:$E$106,0)),0)*10000+IF(AND(ISNUMBER('Remediation Tracker'!K18),'Remediation Tracker'!K18<TODAY(),'Remediation Tracker'!J18<>"Completed"),1000,0)+107-ROW('Remediation Tracker'!E18)) -> 0
AE42: =IF(OR('Remediation Tracker'!E19="",AND('Remediation Tracker'!I19="Approved",'Remediation Tracker'!J19="Completed",ISNUMBER('Remediation Tracker'!L19),'Remediation Tracker'!L19>0,'Remediation Tracker'!L19<=TODAY(),'Remediation Tracker'!N19="Validated",IFERROR(AND('Remediation Tracker'!M19<>"",COUNTIF('Evidence Tracker'!$E$7:$E$106,'Remediation Tracker'!M19)=1,ISNUMBER(INDEX('Evidence Tracker'!$M$7:$M$106,MATCH('Remediation Tracker'!M19,'Evidence Tracker'!$E$7:$E$106,0))),LEN(TRIM(INDEX('Evidence Tracker'!$O$7:$O$106,MATCH('Remediation Tracker'!M19,'Evidence Tracker'!$E$7:$E$106,0))))>0,LEN(TRIM(INDEX('Evidence Tracker'!$P$7:$P$106,MATCH('Remediation Tracker'!M19,'Evidence Tracker'!$E$7:$E$106,0))))>0,COUNTIFS('Evidence Tracker'!$E$7:$E$106,'Remediation Tracker'!M19,'Evidence Tracker'!$F$7:$F$106,'Remediation Tracker'!F19,'Evidence Tracker'!$N$7:$N$106,"Reviewed",'Evidence Tracker'!$Q$7:$Q$106,"Validated",'Evidence Tracker'!$M$7:$M$106,">0",'Evidence Tracker'!$M$7:$M$106,"<="&TODAY())=1),FALSE))),0,IFERROR(INDEX('Risk Register'!$M$7:$M$106,MATCH('Remediation Tracker'!F19,'Risk Register'!$E$7:$E$106,0)),0)*10000+IF(AND(ISNUMBER('Remediation Tracker'!K19),'Remediation Tracker'!K19<TODAY(),'Remediation Tracker'!J19<>"Completed"),1000,0)+107-ROW('Remediation Tracker'!E19)) -> 0
F43: ASSESSMENT WORKSPACE / Risk cards and heatmap follow the filters above. Progress, insights and action priorities below include all records. Planned requests and completed actions do not establish verified closure. | AE43: =IF(OR('Remediation Tracker'!E20="",AND('Remediation Tracker'!I20="Approved",'Remediation Tracker'!J20="Completed",ISNUMBER('Remediation Tracker'!L20),'Remediation Tracker'!L20>0,'Remediation Tracker'!L20<=TODAY(),'Remediation Tracker'!N20="Validated",IFERROR(AND('Remediation Tracker'!M20<>"",COUNTIF('Evidence Tracker'!$E$7:$E$106,'Remediation Tracker'!M20)=1,ISNUMBER(INDEX('Evidence Tracker'!$M$7:$M$106,MATCH('Remediation Tracker'!M20,'Evidence Tracker'!$E$7:$E$106,0))),LEN(TRIM(INDEX('Evidence Tracker'!$O$7:$O$106,MATCH('Remediation Tracker'!M20,'Evidence Tracker'!$E$7:$E$106,0))))>0,LEN(TRIM(INDEX('Evidence Tracker'!$P$7:$P$106,MATCH('Remediation Tracker'!M20,'Evidence Tracker'!$E$7:$E$106,0))))>0,COUNTIFS('Evidence Tracker'!$E$7:$E$106,'Remediation Tracker'!M20,'Evidence Tracker'!$F$7:$F$106,'Remediation Tracker'!F20,'Evidence Tracker'!$N$7:$N$106,"Reviewed",'Evidence Tracker'!$Q$7:$Q$106,"Validated",'Evidence Tracker'!$M$7:$M$106,">0",'Evidence Tracker'!$M$7:$M$106,"<="&TODAY())=1),FALSE))),0,IFERROR(INDEX('Risk Register'!$M$7:$M$106,MATCH('Remediation Tracker'!F20,'Risk Register'!$E$7:$E$106,0)),0)*10000+IF(AND(ISNUMBER('Remediation Tracker'!K20),'Remediation Tracker'!K20<TODAY(),'Remediation Tracker'!J20<>"Completed"),1000,0)+107-ROW('Remediation Tracker'!E20)) -> 0
AE44: =IF(OR('Remediation Tracker'!E21="",AND('Remediation Tracker'!I21="Approved",'Remediation Tracker'!J21="Completed",ISNUMBER('Remediation Tracker'!L21),'Remediation Tracker'!L21>0,'Remediation Tracker'!L21<=TODAY(),'Remediation Tracker'!N21="Validated",IFERROR(AND('Remediation Tracker'!M21<>"",COUNTIF('Evidence Tracker'!$E$7:$E$106,'Remediation Tracker'!M21)=1,ISNUMBER(INDEX('Evidence Tracker'!$M$7:$M$106,MATCH('Remediation Tracker'!M21,'Evidence Tracker'!$E$7:$E$106,0))),LEN(TRIM(INDEX('Evidence Tracker'!$O$7:$O$106,MATCH('Remediation Tracker'!M21,'Evidence Tracker'!$E$7:$E$106,0))))>0,LEN(TRIM(INDEX('Evidence Tracker'!$P$7:$P$106,MATCH('Remediation Tracker'!M21,'Evidence Tracker'!$E$7:$E$106,0))))>0,COUNTIFS('Evidence Tracker'!$E$7:$E$106,'Remediation Tracker'!M21,'Evidence Tracker'!$F$7:$F$106,'Remediation Tracker'!F21,'Evidence Tracker'!$N$7:$N$106,"Reviewed",'Evidence Tracker'!$Q$7:$Q$106,"Validated",'Evidence Tracker'!$M$7:$M$106,">0",'Evidence Tracker'!$M$7:$M$106,"<="&TODAY())=1),FALSE))),0,IFERROR(INDEX('Risk Register'!$M$7:$M$106,MATCH('Remediation Tracker'!F21,'Risk Register'!$E$7:$E$106,0)),0)*10000+IF(AND(ISNUMBER('Remediation Tracker'!K21),'Remediation Tracker'!K21<TODAY(),'Remediation Tracker'!J21<>"Completed"),1000,0)+107-ROW('Remediation Tracker'!E21)) -> 0
AE45: =IF(OR('Remediation Tracker'!E22="",AND('Remediation Tracker'!I22="Approved",'Remediation Tracker'!J22="Completed",ISNUMBER('Remediation Tracker'!L22),'Remediation Tracker'!L22>0,'Remediation Tracker'!L22<=TODAY(),'Remediation Tracker'!N22="Validated",IFERROR(AND('Remediation Tracker'!M22<>"",COUNTIF('Evidence Tracker'!$E$7:$E$106,'Remediation Tracker'!M22)=1,ISNUMBER(INDEX('Evidence Tracker'!$M$7:$M$106,MATCH('Remediation Tracker'!M22,'Evidence Tracker'!$E$7:$E$106,0))),LEN(TRIM(INDEX('Evidence Tracker'!$O$7:$O$106,MATCH('Remediation Tracker'!M22,'Evidence Tracker'!$E$7:$E$106,0))))>0,LEN(TRIM(INDEX('Evidence Tracker'!$P$7:$P$106,MATCH('Remediation Tracker'!M22,'Evidence Tracker'!$E$7:$E$106,0))))>0,COUNTIFS('Evidence Tracker'!$E$7:$E$106,'Remediation Tracker'!M22,'Evidence Tracker'!$F$7:$F$106,'Remediation Tracker'!F22,'Evidence Tracker'!$N$7:$N$106,"Reviewed",'Evidence Tracker'!$Q$7:$Q$106,"Validated",'Evidence Tracker'!$M$7:$M$106,">0",'Evidence Tracker'!$M$7:$M$106,"<="&TODAY())=1),FALSE))),0,IFERROR(INDEX('Risk Register'!$M$7:$M$106,MATCH('Remediation Tracker'!F22,'Risk Register'!$E$7:$E$106,0)),0)*10000+IF(AND(ISNUMBER('Remediation Tracker'!K22),'Remediation Tracker'!K22<TODAY(),'Remediation Tracker'!J22<>"Completed"),1000,0)+107-ROW('Remediation Tracker'!E22)) -> 0
...

Sheet Risk Register
E5: GRC PROJECT 01 / TRAINING WORKSPACE / FOUR SIMULATED RISKS / EVIDENCE AND APPROVAL PENDING
E6: Risk ID | F6: Risk title | G6: Scenario fact / source | H6: Unverified assumptions | I6: Scope / asset | J6: Category | K6: Likelihood | L6: Impact | M6: Inherent score | N6: Inherent rating | O6: Proposed owner | P6: Treatment | Q6: Validation status | R6: Workflow status | S6: Evidence IDs | T6: Residual likelihood | U6: Residual impact | V6: Residual score | W6: Residual rating | X6: Assessment notes | Y6: Dashboard included
E7: R-001 | F7: Missing MFA | G7: Sentinel Defense Solutions' fictional case study identifies that some employees do not have multifactor authentication (MFA) enabled. Source: Project 01 fictional case study. The number of affected accounts and whether privileged accounts are included have not been established. | H7: The number and roles of accounts without MFA, identity provider configuration, MFA enforcement policies, exceptions, compensating controls, and historical authentication activity have not been verified. No account compromise or data breach has been established. | I7: Pending scope confirmation | J7: Identity and access | K7: 3 | L7: 4 | M7: =IF(E7="","",IF(OR(K7="",L7=""),"",IF(AND(ISNUMBER(K7),ISNUMBER(L7),K7>=1,K7<=5,L7>=1,L7<=5,MOD(K7,1)=0,MOD(L7,1)=0),K7*L7,"Invalid input"))) -> 12 | N7: =IF(M7="","",IFERROR(IF(AND(ISNUMBER('Scoring Methodology'!$F$16),ISNUMBER('Scoring Methodology'!$F$17),ISNUMBER('Scoring Methodology'!$F$18),'Scoring Methodology'!$F$16>=2,'Scoring Methodology'!$F$16<'Scoring Methodology'!$F$17,'Scoring Methodology'!$F$17<'Scoring Methodology'!$F$18,'Scoring Methodology'!$F$18<=25,MOD('Scoring Methodology'!$F$16,1)=0,MOD('Scoring Methodology'!$F$17,1)=0,MOD('Scoring Methodology'!$F$18,1)=0),IF(ISNUMBER(M7),IF(M7<'Scoring Methodology'!$F$16,"Low",IF(M7<'Scoring Methodology'!$F$17,"Moderate",IF(M7<'Scoring Methodology'!$F$18,"High","Critical"))),"Invalid input"),"Invalid thresholds"),"Invalid thresholds")) -> High | O7: Security owner - proposed | P7: Mitigate | Q7: Pending validation | R7: Proposed | S7: E-001 | V7: =IF(E7="","",IF(OR(T7="",U7=""),"",IF(AND(ISNUMBER(T7),ISNUMBER(U7),T7>=1,T7<=5,U7>=1,U7<=5,MOD(T7,1)=0,MOD(U7,1)=0),T7*U7,"Invalid input"))) | W7: =IF(V7="","",IFERROR(IF(AND(ISNUMBER('Scoring Methodology'!$F$16),ISNUMBER('Scoring Methodology'!$F$17),ISNUMBER('Scoring Methodology'!$F$18),'Scoring Methodology'!$F$16>=2,'Scoring Methodology'!$F$16<'Scoring Methodology'!$F$17,'Scoring Methodology'!$F$17<'Scoring Methodology'!$F$18,'Scoring Methodology'!$F$18<=25,MOD('Scoring Methodology'!$F$16,1)=0,MOD('Scoring Methodology'!$F$17,1)=0,MOD('Scoring Methodology'!$F$18,1)=0),IF(ISNUMBER(V7),IF(V7<'Scoring Methodology'!$F$16,"Low",IF(V7<'Scoring Methodology'!$F$17,"Moderate",IF(V7<'Scoring Methodology'!$F$18,"High","Critical"))),"Invalid input"),"Invalid thresholds"),"Invalid thresholds")) | X7: =IF(E7="","",IF(AND(ISNUMBER(M7),OR(N7="Low",N7="Moderate",N7="High",N7="Critical")),"Provisional assessment: Likelihood "&K7&"/5 ("&INDEX('Scoring Methodology'!$F$9:$F$13,K7)&") and Impact "&L7&"/5 ("&INDEX('Scoring Methodology'!$G$9:$G$13,L7)&"), resulting in a "&N7&" risk score of "&M7&"/25. ","Provisional assessment: score unavailable; check likelihood, impact and scoring thresholds. ")&_xlfn._LONGTEXT("Inconsistent MFA enforcement increases the possibility of unauthorized account access if credentials are compromised. Potential consequences include exposure of sensitive records, operational disruption, and contractual or financial impacts. Recommend enf","orcing MFA across applicable accounts, prioritizing privileged access, reviewing approved exceptions, and monitoring authentication activity. Validate through identity-provider configurations, account-level MFA coverage reports, exception records, and rel","evant authentication logs. No compromise or confirmed control failure beyond the stated MFA gap has been established.")) -> Provisional assessment: Likelihood 3/5 (Possible) and Impact 4/5 (Major), resulting in a High risk score of 12/25. Inconsistent MFA enforcement increases the possibility of unauthorized account access if credentials are compromised. Potential consequences include exposure of sensitive records, operational disruption, and contractual or financial impacts. Recommend enforcing MFA across applicable accounts, prioritizing privileged access, reviewing approved exceptions, and monitoring authentication activity. Validate through identity-provider configurations, account-level MFA coverage reports, exception records, and relevant authentication logs. No compromise or confirmed control failure beyond the stated MFA gap has been established. | Y7: =IF(E7="",0,IF(AND(OR(Dashboard!$L$7="All",Q7=Dashboard!$L$7),OR(Dashboard!$T$7="All",N7=Dashboard!$T$7)),1,0)) -> 1
E8: R-002 | F8: Excessive Access Permissions | G8: Sentinel Defense Solutions' fictional case scenario identifies concerns that some employees may have access to files beyond their assigned job responsibilities. Source: Project 01 fictional case study. | H8: The number of affected employees, specific file repositories, actual permission assignments, sensitivity of accessible records, effectiveness of existing access controls, and frequency of access reviews have not been verified. | I8: Proposed scope: file repositories containing customer records, employee PII, and contract documentation. Actual repositories, affected users, permission assignments, and data sensitivity require confirmation. | J8: Identity and access | K8: 3 | L8: 4 | M8: =IF(E8="","",IF(OR(K8="",L8=""),"",IF(AND(ISNUMBER(K8),ISNUMBER(L8),K8>=1,K8<=5,L8>=1,L8<=5,MOD(K8,1)=0,MOD(L8,1)=0),K8*L8,"Invalid input"))) -> 12 | N8: =IF(M8="","",IFERROR(IF(AND(ISNUMBER('Scoring Methodology'!$F$16),ISNUMBER('Scoring Methodology'!$F$17),ISNUMBER('Scoring Methodology'!$F$18),'Scoring Methodology'!$F$16>=2,'Scoring Methodology'!$F$16<'Scoring Methodology'!$F$17,'Scoring Methodology'!$F$17<'Scoring Methodology'!$F$18,'Scoring Methodology'!$F$18<=25,MOD('Scoring Methodology'!$F$16,1)=0,MOD('Scoring Methodology'!$F$17,1)=0,MOD('Scoring Methodology'!$F$18,1)=0),IF(ISNUMBER(M8),IF(M8<'Scoring Methodology'!$F$16,"Low",IF(M8<'Scoring Methodology'!$F$17,"Moderate",IF(M8<'Scoring Methodology'!$F$18,"High","Critical"))),"Invalid input"),"Invalid thresholds"),"Invalid thresholds")) -> High | O8: IT Security Manager - proposed | P8: Mitigate | Q8: Pending validation | R8: Proposed | S8: E-002 | V8: =IF(E8="","",IF(OR(T8="",U8=""),"",IF(AND(ISNUMBER(T8),ISNUMBER(U8),T8>=1,T8<=5,U8>=1,U8<=5,MOD(T8,1)=0,MOD(U8,1)=0),T8*U8,"Invalid input"))) | W8: =IF(V8="","",IFERROR(IF(AND(ISNUMBER('Scoring Methodology'!$F$16),ISNUMBER('Scoring Methodology'!$F$17),ISNUMBER('Scoring Methodology'!$F$18),'Scoring Methodology'!$F$16>=2,'Scoring Methodology'!$F$16<'Scoring Methodology'!$F$17,'Scoring Methodology'!$F$17<'Scoring Methodology'!$F$18,'Scoring Methodology'!$F$18<=25,MOD('Scoring Methodology'!$F$16,1)=0,MOD('Scoring Methodology'!$F$17,1)=0,MOD('Scoring Methodology'!$F$18,1)=0),IF(ISNUMBER(V8),IF(V8<'Scoring Methodology'!$F$16,"Low",IF(V8<'Scoring Methodology'!$F$17,"Moderate",IF(V8<'Scoring Methodology'!$F$18,"High","Critical"))),"Invalid input"),"Invalid thresholds"),"Invalid thresholds")) | X8: =IF(E8="","",IF(AND(ISNUMBER(M8),OR(N8="Low",N8="Moderate",N8="High",N8="Critical")),"Provisional assessment: Likelihood "&K8&"/5 ("&INDEX('Scoring Methodology'!$F$9:$F$13,K8)&") and Impact "&L8&"/5 ("&INDEX('Scoring Methodology'!$G$9:$G$13,L8)&"), resulting in a "&N8&" risk score of "&M8&"/25. ","Provisional assessment: score unavailable; check likelihood, impact and scoring thresholds. ")&_xlfn._LONGTEXT("Suspected excessive permissions could allow employees or compromised accounts to access, modify, or disclose sensitive information beyond legitimate business requirements. Recommend validating current permissions against documented job responsibilities, r","emoving unjustified access, enforcing least privilege, and establishing periodic access reviews. Request permission exports, role definitions, access approvals, group memberships, and prior review records. The extent of excessive access, effectiveness of ","existing controls, and any actual unauthorized disclosure remain unverified.")) -> Provisional assessment: Likelihood 3/5 (Possible) and Impact 4/5 (Major), resulting in a High risk score of 12/25. Suspected excessive permissions could allow employees or compromised accounts to access, modify, or disclose sensitive information beyond legitimate business requirements. Recommend validating current permissions against documented job responsibilities, removing unjustified access, enforcing least privilege, and establishing periodic access reviews. Request permission exports, role definitions, access approvals, group memberships, and prior review records. The extent of excessive access, effectiveness of existing controls, and any actual unauthorized disclosure remain unverified. | Y8: =IF(E8="",0,IF(AND(OR(Dashboard!$L$7="All",Q8=Dashboard!$L$7),OR(Dashboard!$T$7="All",N8=Dashboard!$T$7)),1,0)) -> 1
E9: R-003 | F9: Shared Administrator Accounts | G9: Sentinel Defense Solutions' fictional case study states that an external IT support vendor uses shared administrator accounts. Source: Project 01 fictional case study. The account privileges, number of users, affected systems, and existing safeguards have not been established. | H9: The number and identities of vendor personnel using shared administrator accounts, account privileges, affected systems, MFA enforcement, credential-management practices, activity attribution, access approvals, and existing monitoring controls have not been verified. No account compromise, misuse, or security incident has been established. | I9: Proposed scope: shared vendor administrator accounts, systems managed by the external IT provider, and information accessible through those systems. Actual access scope and data sensitivity require confirmation. | J9: Identity and access | K9: 3 | L9: 4 | M9: =IF(E9="","",IF(OR(K9="",L9=""),"",IF(AND(ISNUMBER(K9),ISNUMBER(L9),K9>=1,K9<=5,L9>=1,L9<=5,MOD(K9,1)=0,MOD(L9,1)=0),K9*L9,"Invalid input"))) -> 12 | N9: =IF(M9="","",IFERROR(IF(AND(ISNUMBER('Scoring Methodology'!$F$16),ISNUMBER('Scoring Methodology'!$F$17),ISNUMBER('Scoring Methodology'!$F$18),'Scoring Methodology'!$F$16>=2,'Scoring Methodology'!$F$16<'Scoring Methodology'!$F$17,'Scoring Methodology'!$F$17<'Scoring Methodology'!$F$18,'Scoring Methodology'!$F$18<=25,MOD('Scoring Methodology'!$F$16,1)=0,MOD('Scoring Methodology'!$F$17,1)=0,MOD('Scoring Methodology'!$F$18,1)=0),IF(ISNUMBER(M9),IF(M9<'Scoring Methodology'!$F$16,"Low",IF(M9<'Scoring Methodology'!$F$17,"Moderate",IF(M9<'Scoring Methodology'!$F$18,"High","Critical"))),"Invalid input"),"Invalid thresholds"),"Invalid thresholds")) -> High | O9: IT Security Manager - Proposed | P9: Mitigate | Q9: Pending validation | R9: Proposed | S9: E-003 | V9: =IF(E9="","",IF(OR(T9="",U9=""),"",IF(AND(ISNUMBER(T9),ISNUMBER(U9),T9>=1,T9<=5,U9>=1,U9<=5,MOD(T9,1)=0,MOD(U9,1)=0),T9*U9,"Invalid input"))) | W9: =IF(V9="","",IFERROR(IF(AND(ISNUMBER('Scoring Methodology'!$F$16),ISNUMBER('Scoring Methodology'!$F$17),ISNUMBER('Scoring Methodology'!$F$18),'Scoring Methodology'!$F$16>=2,'Scoring Methodology'!$F$16<'Scoring Methodology'!$F$17,'Scoring Methodology'!$F$17<'Scoring Methodology'!$F$18,'Scoring Methodology'!$F$18<=25,MOD('Scoring Methodology'!$F$16,1)=0,MOD('Scoring Methodology'!$F$17,1)=0,MOD('Scoring Methodology'!$F$18,1)=0),IF(ISNUMBER(V9),IF(V9<'Scoring Methodology'!$F$16,"Low",IF(V9<'Scoring Methodology'!$F$17,"Moderate",IF(V9<'Scoring Methodology'!$F$18,"High","Critical"))),"Invalid input"),"Invalid thresholds"),"Invalid thresholds")) | X9: =IF(E9="","",IF(AND(ISNUMBER(M9),OR(N9="Low",N9="Moderate",N9="High",N9="Critical")),"Provisional assessment: Likelihood "&K9&"/5 ("&INDEX('Scoring Methodology'!$F$9:$F$13,K9)&") and Impact "&L9&"/5 ("&INDEX('Scoring Methodology'!$G$9:$G$13,L9)&"), resulting in a "&N9&" risk score of "&M9&"/25. ","Provisional assessment: score unavailable; check likelihood, impact and scoring thresholds. ")&_xlfn._LONGTEXT("Shared administrator accounts used by an external IT support vendor may reduce individual accountability and complicate access revocation. Unauthorized use or compromise of privileged credentials could result in system changes, disclosure of accessible in","formation, or operational disruption. Recommend confirming account scope and authorized users, replacing shared access with individually attributable privileged identities where feasible, enforcing appropriate MFA and least privilege, and reviewing privil","eged activity monitoring. Validate using privileged-account inventories, vendor access approvals, account permissions, MFA configurations, and dated administrative activity records. No unauthorized activity or incident has been established.")) -> Provisional assessment: Likelihood 3/5 (Possible) and Impact 4/5 (Major), resulting in a High risk score of 12/25. Shared administrator accounts used by an external IT support vendor may reduce individual accountability and complicate access revocation. Unauthorized use or compromise of privileged credentials could result in system changes, disclosure of accessible information, or operational disruption. Recommend confirming account scope and authorized users, replacing shared access with individually attributable privileged identities where feasible, enforcing appropriate MFA and least privilege, and reviewing privileged activity monitoring. Validate using privileged-account inventories, vendor access approvals, account permissions, MFA configurations, and dated administrative activity records. No unauthorized activity or incident has been established. | Y9: =IF(E9="",0,IF(AND(OR(Dashboard!$L$7="All",Q9=Dashboard!$L$7),OR(Dashboard!$T$7="All",N9=Dashboard!$T$7)),1,0)) -> 1
E10: R-004 | F10: Missing Formal Cybersecurity Risk Register | G10: Sentinel Defense Solutions' fictional case study states that the organization does not have a documented cybersecurity risk register. Source: Project 01 fictional case study. The existence and effectiveness of other risk management activities have not been established. | H10: Existing risk identification practices, departmental risk records, risk ownership assignments, assessment methodology, review frequency, escalation procedures, management reporting, treatment approvals, and risk acceptance authority have not been verified. The duration of the documented-register gap and any resulting incidents or losses are unknown. | I10: Enterprise cybersecurity risk identification, assessment, ownership, prioritization, treatment tracking, escalation, and leadership reporting across Sentinel operations and relevant third-party relationships. Actual process coverage and existing safeguards require confirmation. | J10: Governance | K10: 3 | L10: 4 | M10: =IF(E10="","",IF(OR(K10="",L10=""),"",IF(AND(ISNUMBER(K10),ISNUMBER(L10),K10>=1,K10<=5,L10>=1,L10<=5,MOD(K10,1)=0,MOD(L10,1)=0),K10*L10,"Invalid input"))) -> 12 | N10: =IF(M10="","",IFERROR(IF(AND(ISNUMBER('Scoring Methodology'!$F$16),ISNUMBER('Scoring Methodology'!$F$17),ISNUMBER('Scoring Methodology'!$F$18),'Scoring Methodology'!$F$16>=2,'Scoring Methodology'!$F$16<'Scoring Methodology'!$F$17,'Scoring Methodology'!$F$17<'Scoring Methodology'!$F$18,'Scoring Methodology'!$F$18<=25,MOD('Scoring Methodology'!$F$16,1)=0,MOD('Scoring Methodology'!$F$17,1)=0,MOD('Scoring Methodology'!$F$18,1)=0),IF(ISNUMBER(M10),IF(M10<'Scoring Methodology'!$F$16,"Low",IF(M10<'Scoring Methodology'!$F$17,"Moderate",IF(M10<'Scoring Methodology'!$F$18,"High","Critical"))),"Invalid input"),"Invalid thresholds"),"Invalid thresholds")) -> High | O10: IT Security Manager - Proposed | P10: Mitigate | Q10: Pending validation | R10: Proposed | S10: E-004 | V10: =IF(E10="","",IF(OR(T10="",U10=""),"",IF(AND(ISNUMBER(T10),ISNUMBER(U10),T10>=1,T10<=5,U10>=1,U10<=5,MOD(T10,1)=0,MOD(U10,1)=0),T10*U10,"Invalid input"))) | W10: =IF(V10="","",IFERROR(IF(AND(ISNUMBER('Scoring Methodology'!$F$16),ISNUMBER('Scoring Methodology'!$F$17),ISNUMBER('Scoring Methodology'!$F$18),'Scoring Methodology'!$F$16>=2,'Scoring Methodology'!$F$16<'Scoring Methodology'!$F$17,'Scoring Methodology'!$F$17<'Scoring Methodology'!$F$18,'Scoring Methodology'!$F$18<=25,MOD('Scoring Methodology'!$F$16,1)=0,MOD('Scoring Methodology'!$F$17,1)=0,MOD('Scoring Methodology'!$F$18,1)=0),IF(ISNUMBER(V10),IF(V10<'Scoring Methodology'!$F$16,"Low",IF(V10<'Scoring Methodology'!$F$17,"Moderate",IF(V10<'Scoring Methodology'!$F$18,"High","Critical"))),"Invalid input"),"Invalid thresholds"),"Invalid thresholds")) | X10: =IF(E10="","",IF(AND(ISNUMBER(M10),OR(N10="Low",N10="Moderate",N10="High",N10="Critical")),"Provisional assessment: Likelihood "&K10&"/5 ("&INDEX('Scoring Methodology'!$F$9:$F$13,K10)&") and Impact "&L10&"/5 ("&INDEX('Scoring Methodology'!$G$9:$G$13,L10)&"), resulting in a "&N10&" risk score of "&M10&"/25. ","Provisional assessment: score unavailable; check likelihood, impact and scoring thresholds. ")&_xlfn._LONGTEXT("The absence of a documented cybersecurity risk register may limit consistent identification, prioritization, ownership, escalation, and monitoring of cybersecurity risks. A material risk could consequently be overlooked or addressed late, potentially cont","ributing to operational disruption, financial loss, or contractual consequences. Recommend establishing a formal enterprise cybersecurity risk register supported by documented assessment criteria, assigned risk owners, treatment decisions, periodic review","s, escalation thresholds, and management reporting. Validate through existing policies, risk records, leadership meeting records, assigned responsibilities, and evidence of risk review and escalation practices. Other governance processes, actual consequen","ces, and control effectiveness remain unverified.")) -> Provisional assessment: Likelihood 3/5 (Possible) and Impact 4/5 (Major), resulting in a High risk score of 12/25. The absence of a documented cybersecurity risk register may limit consistent identification, prioritization, ownership, escalation, and monitoring of cybersecurity risks. A material risk could consequently be overlooked or addressed late, potentially contributing to operational disruption, financial loss, or contractual consequences. Recommend establishing a formal enterprise cybersecurity risk register supported by documented assessment criteria, assigned risk owners, treatment decisions, periodic reviews, escalation thresholds, and management reporting. Validate through existing policies, risk records, leadership meeting records, assigned responsibilities, and evidence of risk review and escalation practices. Other governance processes, actual consequences, and control effectiveness remain unverified. | Y10: =IF(E10="",0,IF(AND(OR(Dashboard!$L$7="All",Q10=Dashboard!$L$7),OR(Dashboard!$T$7="All",N10=Dashboard!$T$7)),1,0)) -> 1
M11: =IF(E11="","",IF(OR(K11="",L11=""),"",IF(AND(ISNUMBER(K11),ISNUMBER(L11),K11>=1,K11<=5,L11>=1,L11<=5,MOD(K11,1)=0,MOD(L11,1)=0),K11*L11,"Invalid input"))) | N11: =IF(M11="","",IFERROR(IF(AND(ISNUMBER('Scoring Methodology'!$F$16),ISNUMBER('Scoring Methodology'!$F$17),ISNUMBER('Scoring Methodology'!$F$18),'Scoring Methodology'!$F$16>=2,'Scoring Methodology'!$F$16<'Scoring Methodology'!$F$17,'Scoring Methodology'!$F$17<'Scoring Methodology'!$F$18,'Scoring Methodology'!$F$18<=25,MOD('Scoring Methodology'!$F$16,1)=0,MOD('Scoring Methodology'!$F$17,1)=0,MOD('Scoring Methodology'!$F$18,1)=0),IF(ISNUMBER(M11),IF(M11<'Scoring Methodology'!$F$16,"Low",IF(M11<'Scoring Methodology'!$F$17,"Moderate",IF(M11<'Scoring Methodology'!$F$18,"High","Critical"))),"Invalid input"),"Invalid thresholds"),"Invalid thresholds")) | V11: =IF(E11="","",IF(OR(T11="",U11=""),"",IF(AND(ISNUMBER(T11),ISNUMBER(U11),T11>=1,T11<=5,U11>=1,U11<=5,MOD(T11,1)=0,MOD(U11,1)=0),T11*U11,"Invalid input"))) | W11: =IF(V11="","",IFERROR(IF(AND(ISNUMBER('Scoring Methodology'!$F$16),ISNUMBER('Scoring Methodology'!$F$17),ISNUMBER('Scoring Methodology'!$F$18),'Scoring Methodology'!$F$16>=2,'Scoring Methodology'!$F$16<'Scoring Methodology'!$F$17,'Scoring Methodology'!$F$17<'Scoring Methodology'!$F$18,'Scoring Methodology'!$F$18<=25,MOD('Scoring Methodology'!$F$16,1)=0,MOD('Scoring Methodology'!$F$17,1)=0,MOD('Scoring Methodology'!$F$18,1)=0),IF(ISNUMBER(V11),IF(V11<'Scoring Methodology'!$F$16,"Low",IF(V11<'Scoring Methodology'!$F$17,"Moderate",IF(V11<'Scoring Methodology'!$F$18,"High","Critical"))),"Invalid input"),"Invalid thresholds"),"Invalid thresholds")) | Y11: =IF(E11="",0,IF(AND(OR(Dashboard!$L$7="All",Q11=Dashboard!$L$7),OR(Dashboard!$T$7="All",N11=Dashboard!$T$7)),1,0)) -> 0
M12: =IF(E12="","",IF(OR(K12="",L12=""),"",IF(AND(ISNUMBER(K12),ISNUMBER(L12),K12>=1,K12<=5,L12>=1,L12<=5,MOD(K12,1)=0,MOD(L12,1)=0),K12*L12,"Invalid input"))) | N12: =IF(M12="","",IFERROR(IF(AND(ISNUMBER('Scoring Methodology'!$F$16),ISNUMBER('Scoring Methodology'!$F$17),ISNUMBER('Scoring Methodology'!$F$18),'Scoring Methodology'!$F$16>=2,'Scoring Methodology'!$F$16<'Scoring Methodology'!$F$17,'Scoring Methodology'!$F$17<'Scoring Methodology'!$F$18,'Scoring Methodology'!$F$18<=25,MOD('Scoring Methodology'!$F$16,1)=0,MOD('Scoring Methodology'!$F$17,1)=0,MOD('Scoring Methodology'!$F$18,1)=0),IF(ISNUMBER(M12),IF(M12<'Scoring Methodology'!$F$16,"Low",IF(M12<'Scoring Methodology'!$F$17,"Moderate",IF(M12<'Scoring Methodology'!$F$18,"High","Critical"))),"Invalid input"),"Invalid thresholds"),"Invalid thresholds")) | V12: =IF(E12="","",IF(OR(T12="",U12=""),"",IF(AND(ISNUMBER(T12),ISNUMBER(U12),T12>=1,T12<=5,U12>=1,U12<=5,MOD(T12,1)=0,MOD(U12,1)=0),T12*U12,"Invalid input"))) | W12: =IF(V12="","",IFERROR(IF(AND(ISNUMBER('Scoring Methodology'!$F$16),ISNUMBER('Scoring Methodology'!$F$17),ISNUMBER('Scoring Methodology'!$F$18),'Scoring Methodology'!$F$16>=2,'Scoring Methodology'!$F$16<'Scoring Methodology'!$F$17,'Scoring Methodology'!$F$17<'Scoring Methodology'!$F$18,'Scoring Methodology'!$F$18<=25,MOD('Scoring Methodology'!$F$16,1)=0,MOD('Scoring Methodology'!$F$17,1)=0,MOD('Scoring Methodology'!$F$18,1)=0),IF(ISNUMBER(V12),IF(V12<'Scoring Methodology'!$F$16,"Low",IF(V12<'Scoring Methodology'!$F$17,"Moderate",IF(V12<'Scoring Methodology'!$F$18,"High","Critical"))),"Invalid input"),"Invalid thresholds"),"Invalid thresholds")) | Y12: =IF(E12="",0,IF(AND(OR(Dashboard!$L$7="All",Q12=Dashboard!$L$7),OR(Dashboard!$T$7="All",N12=Dashboard!$T$7)),1,0)) -> 0
M13: =IF(E13="","",IF(OR(K13="",L13=""),"",IF(AND(ISNUMBER(K13),ISNUMBER(L13),K13>=1,K13<=5,L13>=1,L13<=5,MOD(K13,1)=0,MOD(L13,1)=0),K13*L13,"Invalid input"))) | N13: =IF(M13="","",IFERROR(IF(AND(ISNUMBER('Scoring Methodology'!$F$16),ISNUMBER('Scoring Methodology'!$F$17),ISNUMBER('Scoring Methodology'!$F$18),'Scoring Methodology'!$F$16>=2,'Scoring Methodology'!$F$16<'Scoring Methodology'!$F$17,'Scoring Methodology'!$F$17<'Scoring Methodology'!$F$18,'Scoring Methodology'!$F$18<=25,MOD('Scoring Methodology'!$F$16,1)=0,MOD('Scoring Methodology'!$F$17,1)=0,MOD('Scoring Methodology'!$F$18,1)=0),IF(ISNUMBER(M13),IF(M13<'Scoring Methodology'!$F$16,"Low",IF(M13<'Scoring Methodology'!$F$17,"Moderate",IF(M13<'Scoring Methodology'!$F$18,"High","Critical"))),"Invalid input"),"Invalid thresholds"),"Invalid thresholds")) | V13: =IF(E13="","",IF(OR(T13="",U13=""),"",IF(AND(ISNUMBER(T13),ISNUMBER(U13),T13>=1,T13<=5,U13>=1,U13<=5,MOD(T13,1)=0,MOD(U13,1)=0),T13*U13,"Invalid input"))) | W13: =IF(V13="","",IFERROR(IF(AND(ISNUMBER('Scoring Methodology'!$F$16),ISNUMBER('Scoring Methodology'!$F$17),ISNUMBER('Scoring Methodology'!$F$18),'Scoring Methodology'!$F$16>=2,'Scoring Methodology'!$F$16<'Scoring Methodology'!$F$17,'Scoring Methodology'!$F$17<'Scoring Methodology'!$F$18,'Scoring Methodology'!$F$18<=25,MOD('Scoring Methodology'!$F$16,1)=0,MOD('Scoring Methodology'!$F$17,1)=0,MOD('Scoring Methodology'!$F$18,1)=0),IF(ISNUMBER(V13),IF(V13<'Scoring Methodology'!$F$16,"Low",IF(V13<'Scoring Methodology'!$F$17,"Moderate",IF(V13<'Scoring Methodology'!$F$18,"High","Critical"))),"Invalid input"),"Invalid thresholds"),"Invalid thresholds")) | Y13: =IF(E13="",0,IF(AND(OR(Dashboard!$L$7="All",Q13=Dashboard!$L$7),OR(Dashboard!$T$7="All",N13=Dashboard!$T$7)),1,0)) -> 0
M14: =IF(E14="","",IF(OR(K14="",L14=""),"",IF(AND(ISNUMBER(K14),ISNUMBER(L14),K14>=1,K14<=5,L14>=1,L14<=5,MOD(K14,1)=0,MOD(L14,1)=0),K14*L14,"Invalid input"))) | N14: =IF(M14="","",IFERROR(IF(AND(ISNUMBER('Scoring Methodology'!$F$16),ISNUMBER('Scoring Methodology'!$F$17),ISNUMBER('Scoring Methodology'!$F$18),'Scoring Methodology'!$F$16>=2,'Scoring Methodology'!$F$16<'Scoring Methodology'!$F$17,'Scoring Methodology'!$F$17<'Scoring Methodology'!$F$18,'Scoring Methodology'!$F$18<=25,MOD('Scoring Methodology'!$F$16,1)=0,MOD('Scoring Methodology'!$F$17,1)=0,MOD('Scoring Methodology'!$F$18,1)=0),IF(ISNUMBER(M14),IF(M14<'Scoring Methodology'!$F$16,"Low",IF(M14<'Scoring Methodology'!$F$17,"Moderate",IF(M14<'Scoring Methodology'!$F$18,"High","Critical"))),"Invalid input"),"Invalid thresholds"),"Invalid thresholds")) | V14: =IF(E14="","",IF(OR(T14="",U14=""),"",IF(AND(ISNUMBER(T14),ISNUMBER(U14),T14>=1,T14<=5,U14>=1,U14<=5,MOD(T14,1)=0,MOD(U14,1)=0),T14*U14,"Invalid input"))) | W14: =IF(V14="","",IFERROR(IF(AND(ISNUMBER('Scoring Methodology'!$F$16),ISNUMBER('Scoring Methodology'!$F$17),ISNUMBER('Scoring Methodology'!$F$18),'Scoring Methodology'!$F$16>=2,'Scoring Methodology'!$F$16<'Scoring Methodology'!$F$17,'Scoring Methodology'!$F$17<'Scoring Methodology'!$F$18,'Scoring Methodology'!$F$18<=25,MOD('Scoring Methodology'!$F$16,1)=0,MOD('Scoring Methodology'!$F$17,1)=0,MOD('Scoring Methodology'!$F$18,1)=0),IF(ISNUMBER(V14),IF(V14<'Scoring Methodology'!$F$16,"Low",IF(V14<'Scoring Methodology'!$F$17,"Moderate",IF(V14<'Scoring Methodology'!$F$18,"High","Critical"))),"Invalid input"),"Invalid thresholds"),"Invalid thresholds")) | Y14: =IF(E14="",0,IF(AND(OR(Dashboard!$L$7="All",Q14=Dashboard!$L$7),OR(Dashboard!$T$7="All",N14=Dashboard!$T$7)),1,0)) -> 0
M15: =IF(E15="","",IF(OR(K15="",L15=""),"",IF(AND(ISNUMBER(K15),ISNUMBER(L15),K15>=1,K15<=5,L15>=1,L15<=5,MOD(K15,1)=0,MOD(L15,1)=0),K15*L15,"Invalid input"))) | N15: =IF(M15="","",IFERROR(IF(AND(ISNUMBER('Scoring Methodology'!$F$16),ISNUMBER('Scoring Methodology'!$F$17),ISNUMBER('Scoring Methodology'!$F$18),'Scoring Methodology'!$F$16>=2,'Scoring Methodology'!$F$16<'Scoring Methodology'!$F$17,'Scoring Methodology'!$F$17<'Scoring Methodology'!$F$18,'Scoring Methodology'!$F$18<=25,MOD('Scoring Methodology'!$F$16,1)=0,MOD('Scoring Methodology'!$F$17,1)=0,MOD('Scoring Methodology'!$F$18,1)=0),IF(ISNUMBER(M15),IF(M15<'Scoring Methodology'!$F$16,"Low",IF(M15<'Scoring Methodology'!$F$17,"Moderate",IF(M15<'Scoring Methodology'!$F$18,"High","Critical"))),"Invalid input"),"Invalid thresholds"),"Invalid thresholds")) | V15: =IF(E15="","",IF(OR(T15="",U15=""),"",IF(AND(ISNUMBER(T15),ISNUMBER(U15),T15>=1,T15<=5,U15>=1,U15<=5,MOD(T15,1)=0,MOD(U15,1)=0),T15*U15,"Invalid input"))) | W15: =IF(V15="","",IFERROR(IF(AND(ISNUMBER('Scoring Methodology'!$F$16),ISNUMBER('Scoring Methodology'!$F$17),ISNUMBER('Scoring Methodology'!$F$18),'Scoring Methodology'!$F$16>=2,'Scoring Methodology'!$F$16<'Scoring Methodology'!$F$17,'Scoring Methodology'!$F$17<'Scoring Methodology'!$F$18,'Scoring Methodology'!$F$18<=25,MOD('Scoring Methodology'!$F$16,1)=0,MOD('Scoring Methodology'!$F$17,1)=0,MOD('Scoring Methodology'!$F$18,1)=0),IF(ISNUMBER(V15),IF(V15<'Scoring Methodology'!$F$16,"Low",IF(V15<'Scoring Methodology'!$F$17,"Moderate",IF(V15<'Scoring Methodology'!$F$18,"High","Critical"))),"Invalid input"),"Invalid thresholds"),"Invalid thresholds")) | Y15: =IF(E15="",0,IF(AND(OR(Dashboard!$L$7="All",Q15=Dashboard!$L$7),OR(Dashboard!$T$7="All",N15=Dashboard!$T$7)),1,0)) -> 0
M16: =IF(E16="","",IF(OR(K16="",L16=""),"",IF(AND(ISNUMBER(K16),ISNUMBER(L16),K16>=1,K16<=5,L16>=1,L16<=5,MOD(K16,1)=0,MOD(L16,1)=0),K16*L16,"Invalid input"))) | N16: =IF(M16="","",IFERROR(IF(AND(ISNUMBER('Scoring Methodology'!$F$16),ISNUMBER('Scoring Methodology'!$F$17),ISNUMBER('Scoring Methodology'!$F$18),'Scoring Methodology'!$F$16>=2,'Scoring Methodology'!$F$16<'Scoring Methodology'!$F$17,'Scoring Methodology'!$F$17<'Scoring Methodology'!$F$18,'Scoring Methodology'!$F$18<=25,MOD('Scoring Methodology'!$F$16,1)=0,MOD('Scoring Methodology'!$F$17,1)=0,MOD('Scoring Methodology'!$F$18,1)=0),IF(ISNUMBER(M16),IF(M16<'Scoring Methodology'!$F$16,"Low",IF(M16<'Scoring Methodology'!$F$17,"Moderate",IF(M16<'Scoring Methodology'!$F$18,"High","Critical"))),"Invalid input"),"Invalid thresholds"),"Invalid thresholds")) | V16: =IF(E16="","",IF(OR(T16="",U16=""),"",IF(AND(ISNUMBER(T16),ISNUMBER(U16),T16>=1,T16<=5,U16>=1,U16<=5,MOD(T16,1)=0,MOD(U16,1)=0),T16*U16,"Invalid input"))) | W16: =IF(V16="","",IFERROR(IF(AND(ISNUMBER('Scoring Methodology'!$F$16),ISNUMBER('Scoring Methodology'!$F$17),ISNUMBER('Scoring Methodology'!$F$18),'Scoring Methodology'!$F$16>=2,'Scoring Methodology'!$F$16<'Scoring Methodology'!$F$17,'Scoring Methodology'!$F$17<'Scoring Methodology'!$F$18,'Scoring Methodology'!$F$18<=25,MOD('Scoring Methodology'!$F$16,1)=0,MOD('Scoring Methodology'!$F$17,1)=0,MOD('Scoring Methodology'!$F$18,1)=0),IF(ISNUMBER(V16),IF(V16<'Scoring Methodology'!$F$16,"Low",IF(V16<'Scoring Methodology'!$F$17,"Moderate",IF(V16<'Scoring Methodology'!$F$18,"High","Critical"))),"Invalid input"),"Invalid thresholds"),"Invalid thresholds")) | Y16: =IF(E16="",0,IF(AND(OR(Dashboard!$L$7="All",Q16=Dashboard!$L$7),OR(Dashboard!$T$7="All",N16=Dashboard!$T$7)),1,0)) -> 0
M17: =IF(E17="","",IF(OR(K17="",L17=""),"",IF(AND(ISNUMBER(K17),ISNUMBER(L17),K17>=1,K17<=5,L17>=1,L17<=5,MOD(K17,1)=0,MOD(L17,1)=0),K17*L17,"Invalid input"))) | N17: =IF(M17="","",IFERROR(IF(AND(ISNUMBER('Scoring Methodology'!$F$16),ISNUMBER('Scoring Methodology'!$F$17),ISNUMBER('Scoring Methodology'!$F$18),'Scoring Methodology'!$F$16>=2,'Scoring Methodology'!$F$16<'Scoring Methodology'!$F$17,'Scoring Methodology'!$F$17<'Scoring Methodology'!$F$18,'Scoring Methodology'!$F$18<=25,MOD('Scoring Methodology'!$F$16,1)=0,MOD('Scoring Methodology'!$F$17,1)=0,MOD('Scoring Methodology'!$F$18,1)=0),IF(ISNUMBER(M17),IF(M17<'Scoring Methodology'!$F$16,"Low",IF(M17<'Scoring Methodology'!$F$17,"Moderate",IF(M17<'Scoring Methodology'!$F$18,"High","Critical"))),"Invalid input"),"Invalid thresholds"),"Invalid thresholds")) | V17: =IF(E17="","",IF(OR(T17="",U17=""),"",IF(AND(ISNUMBER(T17),ISNUMBER(U17),T17>=1,T17<=5,U17>=1,U17<=5,MOD(T17,1)=0,MOD(U17,1)=0),T17*U17,"Invalid input"))) | W17: =IF(V17="","",IFERROR(IF(AND(ISNUMBER('Scoring Methodology'!$F$16),ISNUMBER('Scoring Methodology'!$F$17),ISNUMBER('Scoring Methodology'!$F$18),'Scoring Methodology'!$F$16>=2,'Scoring Methodology'!$F$16<'Scoring Methodology'!$F$17,'Scoring Methodology'!$F$17<'Scoring Methodology'!$F$18,'Scoring Methodology'!$F$18<=25,MOD('Scoring Methodology'!$F$16,1)=0,MOD('Scoring Methodology'!$F$17,1)=0,MOD('Scoring Methodology'!$F$18,1)=0),IF(ISNUMBER(V17),IF(V17<'Scoring Methodology'!$F$16,"Low",IF(V17<'Scoring Methodology'!$F$17,"Moderate",IF(V17<'Scoring Methodology'!$F$18,"High","Critical"))),"Invalid input"),"Invalid thresholds"),"Invalid thresholds")) | Y17: =IF(E17="",0,IF(AND(OR(Dashboard!$L$7="All",Q17=Dashboard!$L$7),OR(Dashboard!$T$7="All",N17=Dashboard!$T$7)),1,0)) -> 0
